<?xml version="1.0" encoding="UTF-8"?>
<!-- Generated by org.testng.reporters.JUnitReportReporter -->
<testsuite skipped="0" hostname="sandeep406701" name="com.rest.api.PlaceOrderApi" tests="21" failures="5" timestamp="09 Jan 2019 12:00:39 GMT" time="5.379" errors="0">
  <testcase name="test_06_verify_order_not_placed_with_incorrect_end_point" time="0.024" classname="com.rest.api.PlaceOrderApi"/>
  <testcase name="test_02_verify_placing_an_order_at_specific_time" time="0.451" classname="com.rest.api.PlaceOrderApi"/>
  <testcase name="test_04_verify_order_not_placed_with_incorrect_location_of_one_stop" time="0.527" classname="com.rest.api.PlaceOrderApi">
    <failure type="java.lang.AssertionError" message="
Expected: is &lt;400&gt;
     but: was &lt;201&gt;">
      <![CDATA[java.lang.AssertionError: 
Expected: is <400>
     but: was <201>
at org.hamcrest.MatcherAssert.assertThat(MatcherAssert.java:20)
at org.hamcrest.MatcherAssert.assertThat(MatcherAssert.java:8)
at com.rest.api.PlaceOrderApi.test_04_verify_order_not_placed_with_incorrect_location_of_one_stop(PlaceOrderApi.java:93)
at sun.reflect.NativeMethodAccessorImpl.invoke0(Native Method)
at sun.reflect.NativeMethodAccessorImpl.invoke(Unknown Source)
at sun.reflect.DelegatingMethodAccessorImpl.invoke(Unknown Source)
at java.lang.reflect.Method.invoke(Unknown Source)
at org.testng.internal.MethodInvocationHelper.invokeMethod(MethodInvocationHelper.java:124)
at org.testng.internal.Invoker.invokeMethod(Invoker.java:583)
at org.testng.internal.Invoker.invokeTestMethod(Invoker.java:719)
at org.testng.internal.Invoker.invokeTestMethods(Invoker.java:989)
at org.testng.internal.TestMethodWorker.invokeTestMethods(TestMethodWorker.java:125)
at org.testng.internal.TestMethodWorker.run(TestMethodWorker.java:109)
at org.testng.TestRunner.privateRun(TestRunner.java:648)
at org.testng.TestRunner.run(TestRunner.java:505)
at org.testng.SuiteRunner.runTest(SuiteRunner.java:455)
at org.testng.SuiteRunner.runSequentially(SuiteRunner.java:450)
at org.testng.SuiteRunner.privateRun(SuiteRunner.java:415)
at org.testng.SuiteRunner.run(SuiteRunner.java:364)
at org.testng.SuiteRunnerWorker.runSuite(SuiteRunnerWorker.java:52)
at org.testng.SuiteRunnerWorker.run(SuiteRunnerWorker.java:84)
at org.testng.TestNG.runSuitesSequentially(TestNG.java:1208)
at org.testng.TestNG.runSuitesLocally(TestNG.java:1137)
at org.testng.TestNG.runSuites(TestNG.java:1049)
at org.testng.TestNG.run(TestNG.java:1017)
at org.testng.remote.AbstractRemoteTestNG.run(AbstractRemoteTestNG.java:114)
at org.testng.remote.RemoteTestNG.initAndRun(RemoteTestNG.java:251)
at org.testng.remote.RemoteTestNG.main(RemoteTestNG.java:77)
]]>
    </failure>
  </testcase> <!-- test_04_verify_order_not_placed_with_incorrect_location_of_one_stop -->
  <testcase name="test_03_verify_order_not_placed_with_invalid_time_format" time="0.031" classname="com.rest.api.PlaceOrderApi"/>
  <testcase name="test_03_verify_order_not_placed_with_invalid_time_format" time="0.032" classname="com.rest.api.PlaceOrderApi"/>
  <testcase name="test_04_verify_order_not_placed_with_incorrect_location_of_one_stop" time="0.379" classname="com.rest.api.PlaceOrderApi">
    <failure type="java.lang.AssertionError" message="
Expected: is &lt;400&gt;
     but: was &lt;201&gt;">
      <![CDATA[java.lang.AssertionError: 
Expected: is <400>
     but: was <201>
at org.hamcrest.MatcherAssert.assertThat(MatcherAssert.java:20)
at org.hamcrest.MatcherAssert.assertThat(MatcherAssert.java:8)
at com.rest.api.PlaceOrderApi.test_04_verify_order_not_placed_with_incorrect_location_of_one_stop(PlaceOrderApi.java:93)
at sun.reflect.NativeMethodAccessorImpl.invoke0(Native Method)
at sun.reflect.NativeMethodAccessorImpl.invoke(Unknown Source)
at sun.reflect.DelegatingMethodAccessorImpl.invoke(Unknown Source)
at java.lang.reflect.Method.invoke(Unknown Source)
at org.testng.internal.MethodInvocationHelper.invokeMethod(MethodInvocationHelper.java:124)
at org.testng.internal.Invoker.invokeMethod(Invoker.java:583)
at org.testng.internal.Invoker.invokeTestMethod(Invoker.java:719)
at org.testng.internal.Invoker.invokeTestMethods(Invoker.java:989)
at org.testng.internal.TestMethodWorker.invokeTestMethods(TestMethodWorker.java:125)
at org.testng.internal.TestMethodWorker.run(TestMethodWorker.java:109)
at org.testng.TestRunner.privateRun(TestRunner.java:648)
at org.testng.TestRunner.run(TestRunner.java:505)
at org.testng.SuiteRunner.runTest(SuiteRunner.java:455)
at org.testng.SuiteRunner.runSequentially(SuiteRunner.java:450)
at org.testng.SuiteRunner.privateRun(SuiteRunner.java:415)
at org.testng.SuiteRunner.run(SuiteRunner.java:364)
at org.testng.SuiteRunnerWorker.runSuite(SuiteRunnerWorker.java:52)
at org.testng.SuiteRunnerWorker.run(SuiteRunnerWorker.java:84)
at org.testng.TestNG.runSuitesSequentially(TestNG.java:1208)
at org.testng.TestNG.runSuitesLocally(TestNG.java:1137)
at org.testng.TestNG.runSuites(TestNG.java:1049)
at org.testng.TestNG.run(TestNG.java:1017)
at org.testng.remote.AbstractRemoteTestNG.run(AbstractRemoteTestNG.java:114)
at org.testng.remote.RemoteTestNG.initAndRun(RemoteTestNG.java:251)
at org.testng.remote.RemoteTestNG.main(RemoteTestNG.java:77)
]]>
    </failure>
  </testcase> <!-- test_04_verify_order_not_placed_with_incorrect_location_of_one_stop -->
  <testcase name="test_05_verify_order_not_placed_with_incorrect_locations_of_stops" time="0.368" classname="com.rest.api.PlaceOrderApi">
    <failure type="java.lang.AssertionError" message="
Expected: is &lt;400&gt;
     but: was &lt;201&gt;">
      <![CDATA[java.lang.AssertionError: 
Expected: is <400>
     but: was <201>
at org.hamcrest.MatcherAssert.assertThat(MatcherAssert.java:20)
at org.hamcrest.MatcherAssert.assertThat(MatcherAssert.java:8)
at com.rest.api.PlaceOrderApi.test_05_verify_order_not_placed_with_incorrect_locations_of_stops(PlaceOrderApi.java:121)
at sun.reflect.NativeMethodAccessorImpl.invoke0(Native Method)
at sun.reflect.NativeMethodAccessorImpl.invoke(Unknown Source)
at sun.reflect.DelegatingMethodAccessorImpl.invoke(Unknown Source)
at java.lang.reflect.Method.invoke(Unknown Source)
at org.testng.internal.MethodInvocationHelper.invokeMethod(MethodInvocationHelper.java:124)
at org.testng.internal.Invoker.invokeMethod(Invoker.java:583)
at org.testng.internal.Invoker.invokeTestMethod(Invoker.java:719)
at org.testng.internal.Invoker.invokeTestMethods(Invoker.java:989)
at org.testng.internal.TestMethodWorker.invokeTestMethods(TestMethodWorker.java:125)
at org.testng.internal.TestMethodWorker.run(TestMethodWorker.java:109)
at org.testng.TestRunner.privateRun(TestRunner.java:648)
at org.testng.TestRunner.run(TestRunner.java:505)
at org.testng.SuiteRunner.runTest(SuiteRunner.java:455)
at org.testng.SuiteRunner.runSequentially(SuiteRunner.java:450)
at org.testng.SuiteRunner.privateRun(SuiteRunner.java:415)
at org.testng.SuiteRunner.run(SuiteRunner.java:364)
at org.testng.SuiteRunnerWorker.runSuite(SuiteRunnerWorker.java:52)
at org.testng.SuiteRunnerWorker.run(SuiteRunnerWorker.java:84)
at org.testng.TestNG.runSuitesSequentially(TestNG.java:1208)
at org.testng.TestNG.runSuitesLocally(TestNG.java:1137)
at org.testng.TestNG.runSuites(TestNG.java:1049)
at org.testng.TestNG.run(TestNG.java:1017)
at org.testng.remote.AbstractRemoteTestNG.run(AbstractRemoteTestNG.java:114)
at org.testng.remote.RemoteTestNG.initAndRun(RemoteTestNG.java:251)
at org.testng.remote.RemoteTestNG.main(RemoteTestNG.java:77)
]]>
    </failure>
  </testcase> <!-- test_05_verify_order_not_placed_with_incorrect_locations_of_stops -->
  <testcase name="test_06_verify_order_not_placed_with_incorrect_end_point" time="0.045" classname="com.rest.api.PlaceOrderApi"/>
  <testcase name="test_06_verify_order_not_placed_with_incorrect_end_point" time="0.030" classname="com.rest.api.PlaceOrderApi"/>
  <testcase name="test_06_verify_order_not_placed_with_incorrect_end_point" time="0.028" classname="com.rest.api.PlaceOrderApi"/>
  <testcase name="test_03_verify_order_not_placed_with_invalid_time_format" time="0.031" classname="com.rest.api.PlaceOrderApi"/>
  <testcase name="test_01_verify_placing_an_order" time="2.233" classname="com.rest.api.PlaceOrderApi"/>
  <testcase name="test_06_verify_order_not_placed_with_incorrect_end_point" time="0.030" classname="com.rest.api.PlaceOrderApi"/>
  <testcase name="test_05_verify_order_not_placed_with_incorrect_locations_of_stops" time="0.446" classname="com.rest.api.PlaceOrderApi">
    <failure type="java.lang.AssertionError" message="
Expected: is &lt;400&gt;
     but: was &lt;201&gt;">
      <![CDATA[java.lang.AssertionError: 
Expected: is <400>
     but: was <201>
at org.hamcrest.MatcherAssert.assertThat(MatcherAssert.java:20)
at org.hamcrest.MatcherAssert.assertThat(MatcherAssert.java:8)
at com.rest.api.PlaceOrderApi.test_05_verify_order_not_placed_with_incorrect_locations_of_stops(PlaceOrderApi.java:121)
at sun.reflect.NativeMethodAccessorImpl.invoke0(Native Method)
at sun.reflect.NativeMethodAccessorImpl.invoke(Unknown Source)
at sun.reflect.DelegatingMethodAccessorImpl.invoke(Unknown Source)
at java.lang.reflect.Method.invoke(Unknown Source)
at org.testng.internal.MethodInvocationHelper.invokeMethod(MethodInvocationHelper.java:124)
at org.testng.internal.Invoker.invokeMethod(Invoker.java:583)
at org.testng.internal.Invoker.invokeTestMethod(Invoker.java:719)
at org.testng.internal.Invoker.invokeTestMethods(Invoker.java:989)
at org.testng.internal.TestMethodWorker.invokeTestMethods(TestMethodWorker.java:125)
at org.testng.internal.TestMethodWorker.run(TestMethodWorker.java:109)
at org.testng.TestRunner.privateRun(TestRunner.java:648)
at org.testng.TestRunner.run(TestRunner.java:505)
at org.testng.SuiteRunner.runTest(SuiteRunner.java:455)
at org.testng.SuiteRunner.runSequentially(SuiteRunner.java:450)
at org.testng.SuiteRunner.privateRun(SuiteRunner.java:415)
at org.testng.SuiteRunner.run(SuiteRunner.java:364)
at org.testng.SuiteRunnerWorker.runSuite(SuiteRunnerWorker.java:52)
at org.testng.SuiteRunnerWorker.run(SuiteRunnerWorker.java:84)
at org.testng.TestNG.runSuitesSequentially(TestNG.java:1208)
at org.testng.TestNG.runSuitesLocally(TestNG.java:1137)
at org.testng.TestNG.runSuites(TestNG.java:1049)
at org.testng.TestNG.run(TestNG.java:1017)
at org.testng.remote.AbstractRemoteTestNG.run(AbstractRemoteTestNG.java:114)
at org.testng.remote.RemoteTestNG.initAndRun(RemoteTestNG.java:251)
at org.testng.remote.RemoteTestNG.main(RemoteTestNG.java:77)
]]>
    </failure>
  </testcase> <!-- test_05_verify_order_not_placed_with_incorrect_locations_of_stops -->
  <testcase name="test_06_verify_order_not_placed_with_incorrect_end_point" time="0.040" classname="com.rest.api.PlaceOrderApi"/>
  <testcase name="test_08_verify_order_not_placed_with_identical_two_stops" time="0.527" classname="com.rest.api.PlaceOrderApi">
    <failure type="java.lang.AssertionError" message="
Expected: is &lt;400&gt;
     but: was &lt;201&gt;">
      <![CDATA[java.lang.AssertionError: 
Expected: is <400>
     but: was <201>
at org.hamcrest.MatcherAssert.assertThat(MatcherAssert.java:20)
at org.hamcrest.MatcherAssert.assertThat(MatcherAssert.java:8)
at com.rest.api.PlaceOrderApi.test_08_verify_order_not_placed_with_identical_two_stops(PlaceOrderApi.java:195)
at sun.reflect.NativeMethodAccessorImpl.invoke0(Native Method)
at sun.reflect.NativeMethodAccessorImpl.invoke(Unknown Source)
at sun.reflect.DelegatingMethodAccessorImpl.invoke(Unknown Source)
at java.lang.reflect.Method.invoke(Unknown Source)
at org.testng.internal.MethodInvocationHelper.invokeMethod(MethodInvocationHelper.java:124)
at org.testng.internal.Invoker.invokeMethod(Invoker.java:583)
at org.testng.internal.Invoker.invokeTestMethod(Invoker.java:719)
at org.testng.internal.Invoker.invokeTestMethods(Invoker.java:989)
at org.testng.internal.TestMethodWorker.invokeTestMethods(TestMethodWorker.java:125)
at org.testng.internal.TestMethodWorker.run(TestMethodWorker.java:109)
at org.testng.TestRunner.privateRun(TestRunner.java:648)
at org.testng.TestRunner.run(TestRunner.java:505)
at org.testng.SuiteRunner.runTest(SuiteRunner.java:455)
at org.testng.SuiteRunner.runSequentially(SuiteRunner.java:450)
at org.testng.SuiteRunner.privateRun(SuiteRunner.java:415)
at org.testng.SuiteRunner.run(SuiteRunner.java:364)
at org.testng.SuiteRunnerWorker.runSuite(SuiteRunnerWorker.java:52)
at org.testng.SuiteRunnerWorker.run(SuiteRunnerWorker.java:84)
at org.testng.TestNG.runSuitesSequentially(TestNG.java:1208)
at org.testng.TestNG.runSuitesLocally(TestNG.java:1137)
at org.testng.TestNG.runSuites(TestNG.java:1049)
at org.testng.TestNG.run(TestNG.java:1017)
at org.testng.remote.AbstractRemoteTestNG.run(AbstractRemoteTestNG.java:114)
at org.testng.remote.RemoteTestNG.initAndRun(RemoteTestNG.java:251)
at org.testng.remote.RemoteTestNG.main(RemoteTestNG.java:77)
]]>
    </failure>
  </testcase> <!-- test_08_verify_order_not_placed_with_identical_two_stops -->
  <testcase name="test_03_verify_order_not_placed_with_invalid_time_format" time="0.042" classname="com.rest.api.PlaceOrderApi"/>
  <testcase name="test_07_verify_order_not_placed_in_past_time" time="0.029" classname="com.rest.api.PlaceOrderApi"/>
  <testcase name="test_03_verify_order_not_placed_with_invalid_time_format" time="0.034" classname="com.rest.api.PlaceOrderApi"/>
  <testcase name="test_06_verify_order_not_placed_with_incorrect_end_point" time="0.022" classname="com.rest.api.PlaceOrderApi"/>
  <testcase name="test_03_verify_order_not_placed_with_invalid_time_format" time="0.030" classname="com.rest.api.PlaceOrderApi"/>
</testsuite> <!-- com.rest.api.PlaceOrderApi -->
