<?xml version="1.0" encoding="UTF-8"?>
<!-- Generated by org.testng.reporters.JUnitReportReporter -->
<testsuite skipped="0" hostname="sandeep406701" name="com.rest.api.PostApi" tests="21" failures="5" timestamp="09 Jan 2019 06:40:17 GMT" time="4.703" errors="0">
  <testcase name="test_03_verify_order_not_placed_with_invalid_time_format" time="0.027" classname="com.rest.api.PostApi"/>
  <testcase name="test_02_verify_placing_an_order_at_specific_time" time="0.487" classname="com.rest.api.PostApi"/>
  <testcase name="test_03_verify_order_not_placed_with_invalid_time_format" time="0.027" classname="com.rest.api.PostApi"/>
  <testcase name="test_05_verify_order_not_placed_with_incorrect_locations_of_stops" time="0.215" classname="com.rest.api.PostApi">
    <failure type="java.lang.AssertionError" message="
Expected: is &lt;400&gt;
     but: was &lt;503&gt;">
      <![CDATA[java.lang.AssertionError: 
Expected: is <400>
     but: was <503>
at org.hamcrest.MatcherAssert.assertThat(MatcherAssert.java:20)
at org.hamcrest.MatcherAssert.assertThat(MatcherAssert.java:8)
at com.rest.api.PostApi.test_05_verify_order_not_placed_with_incorrect_locations_of_stops(PostApi.java:144)
at sun.reflect.NativeMethodAccessorImpl.invoke0(Native Method)
at sun.reflect.NativeMethodAccessorImpl.invoke(Unknown Source)
at sun.reflect.DelegatingMethodAccessorImpl.invoke(Unknown Source)
at java.lang.reflect.Method.invoke(Unknown Source)
at org.testng.internal.MethodInvocationHelper.invokeMethod(MethodInvocationHelper.java:124)
at org.testng.internal.Invoker.invokeMethod(Invoker.java:583)
at org.testng.internal.Invoker.invokeTestMethod(Invoker.java:719)
at org.testng.internal.Invoker.invokeTestMethods(Invoker.java:989)
at org.testng.internal.TestMethodWorker.invokeTestMethods(TestMethodWorker.java:125)
at org.testng.internal.TestMethodWorker.run(TestMethodWorker.java:109)
at org.testng.TestRunner.privateRun(TestRunner.java:648)
at org.testng.TestRunner.run(TestRunner.java:505)
at org.testng.SuiteRunner.runTest(SuiteRunner.java:455)
at org.testng.SuiteRunner.runSequentially(SuiteRunner.java:450)
at org.testng.SuiteRunner.privateRun(SuiteRunner.java:415)
at org.testng.SuiteRunner.run(SuiteRunner.java:364)
at org.testng.SuiteRunnerWorker.runSuite(SuiteRunnerWorker.java:52)
at org.testng.SuiteRunnerWorker.run(SuiteRunnerWorker.java:84)
at org.testng.TestNG.runSuitesSequentially(TestNG.java:1208)
at org.testng.TestNG.runSuitesLocally(TestNG.java:1137)
at org.testng.TestNG.runSuites(TestNG.java:1049)
at org.testng.TestNG.run(TestNG.java:1017)
at org.testng.remote.AbstractRemoteTestNG.run(AbstractRemoteTestNG.java:114)
at org.testng.remote.RemoteTestNG.initAndRun(RemoteTestNG.java:251)
at org.testng.remote.RemoteTestNG.main(RemoteTestNG.java:77)
]]>
    </failure>
  </testcase> <!-- test_05_verify_order_not_placed_with_incorrect_locations_of_stops -->
  <testcase name="test_07_verify_order_not_placed_in_past_time" time="0.025" classname="com.rest.api.PostApi"/>
  <testcase name="test_06_verify_order_not_placed_with_incorrect_end_point" time="0.043" classname="com.rest.api.PostApi"/>
  <testcase name="test_03_verify_order_not_placed_with_invalid_time_format" time="0.025" classname="com.rest.api.PostApi"/>
  <testcase name="test_04_verify_order_not_placed_with_incorrect_location_of_one_stop" time="0.209" classname="com.rest.api.PostApi">
    <failure type="java.lang.AssertionError" message="
Expected: is &lt;400&gt;
     but: was &lt;503&gt;">
      <![CDATA[java.lang.AssertionError: 
Expected: is <400>
     but: was <503>
at org.hamcrest.MatcherAssert.assertThat(MatcherAssert.java:20)
at org.hamcrest.MatcherAssert.assertThat(MatcherAssert.java:8)
at com.rest.api.PostApi.test_04_verify_order_not_placed_with_incorrect_location_of_one_stop(PostApi.java:122)
at sun.reflect.NativeMethodAccessorImpl.invoke0(Native Method)
at sun.reflect.NativeMethodAccessorImpl.invoke(Unknown Source)
at sun.reflect.DelegatingMethodAccessorImpl.invoke(Unknown Source)
at java.lang.reflect.Method.invoke(Unknown Source)
at org.testng.internal.MethodInvocationHelper.invokeMethod(MethodInvocationHelper.java:124)
at org.testng.internal.Invoker.invokeMethod(Invoker.java:583)
at org.testng.internal.Invoker.invokeTestMethod(Invoker.java:719)
at org.testng.internal.Invoker.invokeTestMethods(Invoker.java:989)
at org.testng.internal.TestMethodWorker.invokeTestMethods(TestMethodWorker.java:125)
at org.testng.internal.TestMethodWorker.run(TestMethodWorker.java:109)
at org.testng.TestRunner.privateRun(TestRunner.java:648)
at org.testng.TestRunner.run(TestRunner.java:505)
at org.testng.SuiteRunner.runTest(SuiteRunner.java:455)
at org.testng.SuiteRunner.runSequentially(SuiteRunner.java:450)
at org.testng.SuiteRunner.privateRun(SuiteRunner.java:415)
at org.testng.SuiteRunner.run(SuiteRunner.java:364)
at org.testng.SuiteRunnerWorker.runSuite(SuiteRunnerWorker.java:52)
at org.testng.SuiteRunnerWorker.run(SuiteRunnerWorker.java:84)
at org.testng.TestNG.runSuitesSequentially(TestNG.java:1208)
at org.testng.TestNG.runSuitesLocally(TestNG.java:1137)
at org.testng.TestNG.runSuites(TestNG.java:1049)
at org.testng.TestNG.run(TestNG.java:1017)
at org.testng.remote.AbstractRemoteTestNG.run(AbstractRemoteTestNG.java:114)
at org.testng.remote.RemoteTestNG.initAndRun(RemoteTestNG.java:251)
at org.testng.remote.RemoteTestNG.main(RemoteTestNG.java:77)
]]>
    </failure>
  </testcase> <!-- test_04_verify_order_not_placed_with_incorrect_location_of_one_stop -->
  <testcase name="test_03_verify_order_not_placed_with_invalid_time_format" time="0.035" classname="com.rest.api.PostApi"/>
  <testcase name="test_03_verify_order_not_placed_with_invalid_time_format" time="0.043" classname="com.rest.api.PostApi"/>
  <testcase name="test_01_verify_placing_an_order" time="2.181" classname="com.rest.api.PostApi"/>
  <testcase name="test_05_verify_order_not_placed_with_incorrect_locations_of_stops" time="0.202" classname="com.rest.api.PostApi">
    <failure type="java.lang.AssertionError" message="
Expected: is &lt;400&gt;
     but: was &lt;503&gt;">
      <![CDATA[java.lang.AssertionError: 
Expected: is <400>
     but: was <503>
at org.hamcrest.MatcherAssert.assertThat(MatcherAssert.java:20)
at org.hamcrest.MatcherAssert.assertThat(MatcherAssert.java:8)
at com.rest.api.PostApi.test_05_verify_order_not_placed_with_incorrect_locations_of_stops(PostApi.java:144)
at sun.reflect.NativeMethodAccessorImpl.invoke0(Native Method)
at sun.reflect.NativeMethodAccessorImpl.invoke(Unknown Source)
at sun.reflect.DelegatingMethodAccessorImpl.invoke(Unknown Source)
at java.lang.reflect.Method.invoke(Unknown Source)
at org.testng.internal.MethodInvocationHelper.invokeMethod(MethodInvocationHelper.java:124)
at org.testng.internal.Invoker.invokeMethod(Invoker.java:583)
at org.testng.internal.Invoker.invokeTestMethod(Invoker.java:719)
at org.testng.internal.Invoker.invokeTestMethods(Invoker.java:989)
at org.testng.internal.TestMethodWorker.invokeTestMethods(TestMethodWorker.java:125)
at org.testng.internal.TestMethodWorker.run(TestMethodWorker.java:109)
at org.testng.TestRunner.privateRun(TestRunner.java:648)
at org.testng.TestRunner.run(TestRunner.java:505)
at org.testng.SuiteRunner.runTest(SuiteRunner.java:455)
at org.testng.SuiteRunner.runSequentially(SuiteRunner.java:450)
at org.testng.SuiteRunner.privateRun(SuiteRunner.java:415)
at org.testng.SuiteRunner.run(SuiteRunner.java:364)
at org.testng.SuiteRunnerWorker.runSuite(SuiteRunnerWorker.java:52)
at org.testng.SuiteRunnerWorker.run(SuiteRunnerWorker.java:84)
at org.testng.TestNG.runSuitesSequentially(TestNG.java:1208)
at org.testng.TestNG.runSuitesLocally(TestNG.java:1137)
at org.testng.TestNG.runSuites(TestNG.java:1049)
at org.testng.TestNG.run(TestNG.java:1017)
at org.testng.remote.AbstractRemoteTestNG.run(AbstractRemoteTestNG.java:114)
at org.testng.remote.RemoteTestNG.initAndRun(RemoteTestNG.java:251)
at org.testng.remote.RemoteTestNG.main(RemoteTestNG.java:77)
]]>
    </failure>
  </testcase> <!-- test_05_verify_order_not_placed_with_incorrect_locations_of_stops -->
  <testcase name="test_03_verify_order_not_placed_with_invalid_time_format" time="0.054" classname="com.rest.api.PostApi"/>
  <testcase name="test_06_verify_order_not_placed_with_incorrect_end_point" time="0.029" classname="com.rest.api.PostApi"/>
  <testcase name="test_08_verify_order_not_placed_with_identical_two_stops" time="0.209" classname="com.rest.api.PostApi">
    <failure type="java.lang.AssertionError" message="
Expected: is &lt;400&gt;
     but: was &lt;503&gt;">
      <![CDATA[java.lang.AssertionError: 
Expected: is <400>
     but: was <503>
at org.hamcrest.MatcherAssert.assertThat(MatcherAssert.java:20)
at org.hamcrest.MatcherAssert.assertThat(MatcherAssert.java:8)
at com.rest.api.PostApi.test_08_verify_order_not_placed_with_identical_two_stops(PostApi.java:197)
at sun.reflect.NativeMethodAccessorImpl.invoke0(Native Method)
at sun.reflect.NativeMethodAccessorImpl.invoke(Unknown Source)
at sun.reflect.DelegatingMethodAccessorImpl.invoke(Unknown Source)
at java.lang.reflect.Method.invoke(Unknown Source)
at org.testng.internal.MethodInvocationHelper.invokeMethod(MethodInvocationHelper.java:124)
at org.testng.internal.Invoker.invokeMethod(Invoker.java:583)
at org.testng.internal.Invoker.invokeTestMethod(Invoker.java:719)
at org.testng.internal.Invoker.invokeTestMethods(Invoker.java:989)
at org.testng.internal.TestMethodWorker.invokeTestMethods(TestMethodWorker.java:125)
at org.testng.internal.TestMethodWorker.run(TestMethodWorker.java:109)
at org.testng.TestRunner.privateRun(TestRunner.java:648)
at org.testng.TestRunner.run(TestRunner.java:505)
at org.testng.SuiteRunner.runTest(SuiteRunner.java:455)
at org.testng.SuiteRunner.runSequentially(SuiteRunner.java:450)
at org.testng.SuiteRunner.privateRun(SuiteRunner.java:415)
at org.testng.SuiteRunner.run(SuiteRunner.java:364)
at org.testng.SuiteRunnerWorker.runSuite(SuiteRunnerWorker.java:52)
at org.testng.SuiteRunnerWorker.run(SuiteRunnerWorker.java:84)
at org.testng.TestNG.runSuitesSequentially(TestNG.java:1208)
at org.testng.TestNG.runSuitesLocally(TestNG.java:1137)
at org.testng.TestNG.runSuites(TestNG.java:1049)
at org.testng.TestNG.run(TestNG.java:1017)
at org.testng.remote.AbstractRemoteTestNG.run(AbstractRemoteTestNG.java:114)
at org.testng.remote.RemoteTestNG.initAndRun(RemoteTestNG.java:251)
at org.testng.remote.RemoteTestNG.main(RemoteTestNG.java:77)
]]>
    </failure>
  </testcase> <!-- test_08_verify_order_not_placed_with_identical_two_stops -->
  <testcase name="test_06_verify_order_not_placed_with_incorrect_end_point" time="0.028" classname="com.rest.api.PostApi"/>
  <testcase name="test_06_verify_order_not_placed_with_incorrect_end_point" time="0.022" classname="com.rest.api.PostApi"/>
  <testcase name="test_06_verify_order_not_placed_with_incorrect_end_point" time="0.595" classname="com.rest.api.PostApi"/>
  <testcase name="test_04_verify_order_not_placed_with_incorrect_location_of_one_stop" time="0.201" classname="com.rest.api.PostApi">
    <failure type="java.lang.AssertionError" message="
Expected: is &lt;400&gt;
     but: was &lt;503&gt;">
      <![CDATA[java.lang.AssertionError: 
Expected: is <400>
     but: was <503>
at org.hamcrest.MatcherAssert.assertThat(MatcherAssert.java:20)
at org.hamcrest.MatcherAssert.assertThat(MatcherAssert.java:8)
at com.rest.api.PostApi.test_04_verify_order_not_placed_with_incorrect_location_of_one_stop(PostApi.java:122)
at sun.reflect.NativeMethodAccessorImpl.invoke0(Native Method)
at sun.reflect.NativeMethodAccessorImpl.invoke(Unknown Source)
at sun.reflect.DelegatingMethodAccessorImpl.invoke(Unknown Source)
at java.lang.reflect.Method.invoke(Unknown Source)
at org.testng.internal.MethodInvocationHelper.invokeMethod(MethodInvocationHelper.java:124)
at org.testng.internal.Invoker.invokeMethod(Invoker.java:583)
at org.testng.internal.Invoker.invokeTestMethod(Invoker.java:719)
at org.testng.internal.Invoker.invokeTestMethods(Invoker.java:989)
at org.testng.internal.TestMethodWorker.invokeTestMethods(TestMethodWorker.java:125)
at org.testng.internal.TestMethodWorker.run(TestMethodWorker.java:109)
at org.testng.TestRunner.privateRun(TestRunner.java:648)
at org.testng.TestRunner.run(TestRunner.java:505)
at org.testng.SuiteRunner.runTest(SuiteRunner.java:455)
at org.testng.SuiteRunner.runSequentially(SuiteRunner.java:450)
at org.testng.SuiteRunner.privateRun(SuiteRunner.java:415)
at org.testng.SuiteRunner.run(SuiteRunner.java:364)
at org.testng.SuiteRunnerWorker.runSuite(SuiteRunnerWorker.java:52)
at org.testng.SuiteRunnerWorker.run(SuiteRunnerWorker.java:84)
at org.testng.TestNG.runSuitesSequentially(TestNG.java:1208)
at org.testng.TestNG.runSuitesLocally(TestNG.java:1137)
at org.testng.TestNG.runSuites(TestNG.java:1049)
at org.testng.TestNG.run(TestNG.java:1017)
at org.testng.remote.AbstractRemoteTestNG.run(AbstractRemoteTestNG.java:114)
at org.testng.remote.RemoteTestNG.initAndRun(RemoteTestNG.java:251)
at org.testng.remote.RemoteTestNG.main(RemoteTestNG.java:77)
]]>
    </failure>
  </testcase> <!-- test_04_verify_order_not_placed_with_incorrect_location_of_one_stop -->
  <testcase name="test_06_verify_order_not_placed_with_incorrect_end_point" time="0.023" classname="com.rest.api.PostApi"/>
  <testcase name="test_06_verify_order_not_placed_with_incorrect_end_point" time="0.023" classname="com.rest.api.PostApi"/>
</testsuite> <!-- com.rest.api.PostApi -->
